[32m2024-09-02 13:51:02 +0530[0m - dagster - [34mDEBUG[0m - __ASSET_JOB_0 - 7a31cd43-f866-4765-a901-8d608041dddc - 43339 - LOGS_CAPTURED - Started capturing logs in process (pid: 43339).
[32m2024-09-02 13:51:02 +0530[0m - dagster - [34mDEBUG[0m - __ASSET_JOB_0 - 7a31cd43-f866-4765-a901-8d608041dddc - 43339 - frequent_earthquake_location - STEP_START - Started execution of step "frequent_earthquake_location".
[32m2024-09-02 13:51:04 +0530[0m - dagster - [34mERROR[0m - [31m__ASSET_JOB_0 - 7a31cd43-f866-4765-a901-8d608041dddc - 43339 - frequent_earthquake_location - STEP_FAILURE - Execution of step "frequent_earthquake_location" failed.

dagster._core.errors.DagsterExecutionStepExecutionError: Error occurred while executing op "frequent_earthquake_location"::

TypeError: __new__() got an unexpected keyword argument 'output'

Stack Trace:
  File "/Users/ayusharma/Documents/demo/Office_Project/office_project_001/.venv/lib/python3.9/site-packages/dagster/_core/execution/plan/utils.py", line 54, in op_execution_error_boundary
    yield
  File "/Users/ayusharma/Documents/demo/Office_Project/office_project_001/.venv/lib/python3.9/site-packages/dagster/_utils/__init__.py", line 478, in iterate_with_context
    next_output = next(iterator)
  File "/Users/ayusharma/Documents/demo/Office_Project/office_project_001/.venv/lib/python3.9/site-packages/dagster/_core/execution/plan/compute_generator.py", line 141, in _coerce_op_compute_fn_to_iterator
    result = invoke_compute_fn(
  File "/Users/ayusharma/Documents/demo/Office_Project/office_project_001/.venv/lib/python3.9/site-packages/dagster/_core/execution/plan/compute_generator.py", line 129, in invoke_compute_fn
    return fn(context, **args_to_pass) if context_arg_provided else fn(**args_to_pass)
  File "/Users/ayusharma/Documents/demo/Office_Project/office_project_001/usgs_pipeline/usgs_pipeline/assets/final_stage.py", line 48, in frequent_earthquake_location
    return MaterializeResult(
[0m
