[32m2024-09-02 13:28:28 +0530[0m - dagster - [34mDEBUG[0m - __ASSET_JOB_0 - 07a34894-f3b5-4865-9454-422cb548697f - 41097 - LOGS_CAPTURED - Started capturing logs in process (pid: 41097).
[32m2024-09-02 13:28:28 +0530[0m - dagster - [34mDEBUG[0m - __ASSET_JOB_0 - 07a34894-f3b5-4865-9454-422cb548697f - 41097 - frequent_earthquake_location - STEP_START - Started execution of step "frequent_earthquake_location".
[32m2024-09-02 13:28:29 +0530[0m - dagster - [34mERROR[0m - [31m__ASSET_JOB_0 - 07a34894-f3b5-4865-9454-422cb548697f - 41097 - frequent_earthquake_location - STEP_FAILURE - Execution of step "frequent_earthquake_location" failed.

dagster._core.errors.DagsterExecutionStepExecutionError: Error occurred while executing op "frequent_earthquake_location"::

snowflake.connector.errors.ProgrammingError: 002003 (42S02): SQL compilation error:
Object 'EARTHQUAKE_FACTS' does not exist or not authorized.

Stack Trace:
  File "/Users/ayusharma/Documents/demo/Office_Project/office_project_001/.venv/lib/python3.9/site-packages/dagster/_core/execution/plan/utils.py", line 54, in op_execution_error_boundary
    yield
  File "/Users/ayusharma/Documents/demo/Office_Project/office_project_001/.venv/lib/python3.9/site-packages/dagster/_utils/__init__.py", line 478, in iterate_with_context
    next_output = next(iterator)
  File "/Users/ayusharma/Documents/demo/Office_Project/office_project_001/.venv/lib/python3.9/site-packages/dagster/_core/execution/plan/compute_generator.py", line 141, in _coerce_op_compute_fn_to_iterator
    result = invoke_compute_fn(
  File "/Users/ayusharma/Documents/demo/Office_Project/office_project_001/.venv/lib/python3.9/site-packages/dagster/_core/execution/plan/compute_generator.py", line 129, in invoke_compute_fn
    return fn(context, **args_to_pass) if context_arg_provided else fn(**args_to_pass)
  File "/Users/ayusharma/Documents/demo/Office_Project/office_project_001/usgs_pipeline/usgs_pipeline/assets/final_stage.py", line 29, in frequent_earthquake_location
    cursor.execute(query)
  File "/Users/ayusharma/Documents/demo/Office_Project/office_project_001/.venv/lib/python3.9/site-packages/snowflake/connector/cursor.py", line 1087, in execute
    Error.errorhandler_wrapper(self.connection, self, error_class, errvalue)
  File "/Users/ayusharma/Documents/demo/Office_Project/office_project_001/.venv/lib/python3.9/site-packages/snowflake/connector/errors.py", line 284, in errorhandler_wrapper
    handed_over = Error.hand_to_other_handler(
  File "/Users/ayusharma/Documents/demo/Office_Project/office_project_001/.venv/lib/python3.9/site-packages/snowflake/connector/errors.py", line 339, in hand_to_other_handler
    cursor.errorhandler(connection, cursor, error_class, error_value)
  File "/Users/ayusharma/Documents/demo/Office_Project/office_project_001/.venv/lib/python3.9/site-packages/snowflake/connector/errors.py", line 215, in default_errorhandler
    raise error_class(
[0m
